Workbook

Sheet Management Summary
C2: Total | G2: Coding | K2: Meetings | O2: Systems Analysis | S2: Overhead
C3: Budgeted | D3: Actual | E3: Deficit | G3: Budgeted | H3: Actual | I3: Deficit | K3: Budgeted | L3: Actual | M3: Deficit | O3: Budgeted | P3: Actual | Q3: Deficit | S3: Budgeted | T3: Actual | U3: Deficit
B4: Anne | C4: =(G4+K4 +O4+S4) -> 10100 | D4: =(H4+L4 +P4+T4) -> 6800 | E4: =(C4-D4) -> 3300 | G4: =(Gantt!$C12)*100 -> 5000 | H4: =(Gantt!$D12)*100 -> 800 | I4: =(G4-H4) -> 4200 | K4: 1000 | L4: =Meetings!B4*100 -> 2100 | M4: =(K4-L4) -> -1100 | O4: =(SA!C5)*100 -> 1100 | P4: =(SA!D5)*100 -> 1300 | Q4: =(O4-P4) -> -200 | S4: 3000 | T4: =Overhead!B9*100 -> 2600 | U4: =(S4-T4) -> 400
B5: Bill | C5: =(G5+K5 +O5+S5) -> 5100 | D5: =(H5+L5 +P5+T5) -> 4000 | E5: =(C5-D5) -> 1100 | G5: =(Gantt!$C18)*100 -> 0 | H5: =(Gantt!$D18)*100 -> 0 | I5: =(G5-H5) -> 0 | K5: 1000 | L5: =Meetings!B5*100 -> 900 | M5: =(K5-L5) -> 100 | O5: =(SA!C9)*100 -> 1100 | P5: =(SA!D9)*100 -> 1000 | Q5: =(O5-P5) -> 100 | S5: 3000 | T5: =Overhead!C9*100 -> 2100 | U5: =(S5-T5) -> 900
B6: Chris | C6: =(G6+K6 +O6+S6) -> 5100 | D6: =(H6+L6 +P6+T6) -> 6900 | E6: =(C6-D6) -> -1800 | G6: =(Gantt!$C23)*100 -> 0 | H6: =(Gantt!$D23)*100 -> 0 | I6: =(G6-H6) -> 0 | K6: 1000 | L6: =Meetings!B6*100 -> 1100 | M6: =(K6-L6) -> -100 | O6: =(SA!C15)*100 -> 1100 | P6: =(SA!D15)*100 -> 1500 | Q6: =(O6-P6) -> -400 | S6: 3000 | T6: =Overhead!D9*100 -> 4300 | U6: =(S6-T6) -> -1300
B7: Dan | C7: =(G7+K7 +O7+S7) -> 5100 | D7: =(H7+L7 +P7+T7) -> 7900 | E7: =(C7-D7) -> -2800 | G7: =(Gantt!$C480)*100 -> 0 | H7: =(Gantt!$D36)*100 -> 1800 | I7: =(G7-H7) -> -1800 | K7: 1000 | L7: =Meetings!B7*100 -> 1500 | M7: =(K7-L7) -> -500 | O7: =(SA!C19)*100 -> 1100 | P7: =(SA!D19)*100 -> 1100 | Q7: =(O7-P7) -> 0 | S7: 3000 | T7: =Overhead!E9*100 -> 3500 | U7: =(S7-T7) -> -500
B8: Eric | C8: =(G8+K8 +O8+S8) -> 6400 | D8: =(H8+L8 +P8+T8) -> 5900 | E8: =(C8-D8) -> 500 | G8: =(Gantt!$C49)*100 -> 1300 | H8: =(Gantt!$D49)*100 -> 600 | I8: =(G8-H8) -> 700 | K8: 1000 | L8: =Meetings!B8*100 -> 900 | M8: =(K8-L8) -> 100 | O8: =(SA!C23)*100 -> 1100 | P8: =(SA!D23)*100 -> 900 | Q8: =(O8-P8) -> 200 | S8: 3000 | T8: =Overhead!F9*100 -> 3500 | U8: =(S8-T8) -> -500
B9: Fran | C9: =(G9+K9 +O9+S9) -> 8500 | D9: =(H9+L9 +P9+T9) -> 9000 | E9: =(C9-D9) -> -500 | G9: =(Gantt!$C58)*100 -> 3400 | H9: =(Gantt!$D58)*100 -> 3300 | I9: =(G9-H9) -> 100 | K9: 1000 | L9: =Meetings!B9*100 -> 900 | M9: =(K9-L9) -> 100 | O9: =(SA!C27)*100 -> 1100 | P9: =(SA!D27)*100 -> 1300 | Q9: =(O9-P9) -> -200 | S9: 3000 | T9: =Overhead!G9*100 -> 3500 | U9: =(S9-T9) -> -500
B10: Total | C10: =SUM(C4:C9) -> 40300 | D10: =SUM(D4:D9) -> 40500 | E10: =SUM(E4:E9) -> -200 | G10: =SUM(G4:G9) -> 9700 | H10: =SUM(H4:H9) -> 6500 | I10: =SUM(I4:I9) -> 3200 | K10: =SUM(K4:K9) -> 6000 | L10: =SUM(L4:L9) -> 7400 | M10: =SUM(M4:M9) -> -1400 | O10: =SUM(O4:O9) -> 6600 | P10: =SUM(P4:P9) -> 7100 | Q10: =SUM(Q4:Q9) -> -500 | S10: =SUM(S4:S9) -> 18000 | T10: =SUM(T4:T9) -> 19500 | U10: =SUM(U4:U9) -> -1500

Sheet Gantt
A1: S.N. | C1: predicted time(hrs) | D1: time spent(hrs) | E1: Precedent | F1: Status | G1: key | H1: complete | I1: this week | J1: planned
B2: Aiden | G2: 1 | H2: =(G2+1) -> 2 | I2: =(H2+1) -> 3 | J2: =(I2+1) -> 4 | K2: =(J2+1) -> 5 | L2: =(K2+1) -> 6 | M2: =(L2+1) -> 7 | N2: =(M2+1) -> 8 | O2: =(N2+1) -> 9 | ... BM2: =(BL2+1) -> 59
A3: 1 | B3: Player Idle Sprites | C3: 4 | D3: 3 | E3: N/A | F3: complete | G3: =($F3) -> complete | H3: =($F3) -> complete | I3: =($F3) -> complete | J3: =($F3) -> complete
A4: 2 | B4: Player Movement Sprites | C4: 5 | D4: 5 | E4: 1 | F4: complete | K4: =($F4) -> complete | L4: =($F4) -> complete | M4: =($F4) -> complete | N4: =($F4) -> complete | O4: =($F4) -> complete
A5: 3 | B5: Player Combat Sprites | C5: 7 | E5: 1 | F5: this week | P5: =($F5) -> this week | Q5: =($F5) -> this week | R5: =($F5) -> this week | S5: =($F5) -> this week | T5: =($F5) -> this week
A6: 4 | B6: Health Pickups | C6: 4 | E6: N/A | F6: this week | U6: =($F6) -> this week
A7: 5 | B7: Weapons | C7: 10 | E7: N/A | F7: planned | V7: =($F7) -> planned | W7: =($F7) -> planned | X7: =($F7) -> planned
A8: 6 | B8: Enemy Movement Sprites | C8: 5 | E8: N/A | F8: planned | Y8: =($F8) -> planned | Z8: =($F8) -> planned | AA8: =($F8) -> planned
A9: 7 | B9: Enemy Combat Sprites | C9: 6 | E9: 6 | F9: planned | AB9: =($F9) -> planned | AC9: =($F9) -> planned | AD9: =($F9) -> planned | AE9: =($F9) -> planned
A10: 8 | B10: Boss Sprites | C10: 4 | E10: N/A | F10: planned | AF10: =($F10) -> planned | AG10: =($F10) -> planned | AH10: =($F10) -> planned | AI10: =($F10) -> planned | AJ10: =($F10) -> planned | AK10: =($F10) -> planned | AL10: =($F10) -> planned | AM10: =($F10) -> planned | ... AR10: =($F10) -> planned
A11: 9 | B11: Boss Combat Sprites | C11: 5 | E11: 8 | F11: planned | AS11: =($F11) -> planned
B12: totals | C12: =SUM(C3:C11) -> 50 | D12: =SUM(D3:D11) -> 8
B13: Ro
A14: 1 | F14: planned
A15: 2 | F15: planned
A16: 3 | F16: planned
A17: 4 | F17: planned
B18: totals | C18: =SUM(C14:C17) -> 0 | D18: =SUM(D14:D17) -> 0
B19: Jaskaran
A20: 1 | F20: planned
A21: 2 | F21: planned
A22: 3 | F22: planned
B23: totals | C23: =SUM(C20:C22) -> 0 | D23: =SUM(D20:D22) -> 0
B24: Safal
A25: 1 | B25: Player development | C25: 4 | D25: 3 | E25: N/A | F25: complete | G25: =($F25) -> complete | H25: =($F25) -> complete | I25: =($F25) -> complete | J25: =($F25) -> complete
A26: 2 | B26: Actions(Player) | C26: 3 | D26: 3 | E26: 1 | F26: complete | K26: =($F26) -> complete | L26: =($F26) -> complete | M26: =($F26) -> complete
A27: 3 | B27: Game Mechanics(logic and development) | C27: 8 | D27: 9 | E27: 2 | F27: complete | N27: =($F27) -> complete | O27: =($F27) -> complete | P27: =($F27) -> complete | Q27: =($F27) -> complete | R27: =($F27) -> complete | S27: =($F27) -> complete | T27: =($F27) -> complete | U27: =($F27) -> complete
A28: 4 | B28: Attack Enemy | C28: 4 | D28: 3 | E28: 3 | F28: complete | V28: =($F28) -> complete | W28: =($F28) -> complete | X28: =($F28) -> complete | Y28: =($F28) -> complete
A29: 5 | B29: logic for game win/loose | C29: 6 | E29: 2, 3 | F29: this week | V29: =($F29) -> this week | W29: =($F29) -> this week | X29: =($F29) -> this week | Y29: =($F29) -> this week | Z29: =($F29) -> this week | AA29: =($F29) -> this week
A30: 6 | B30: logic for player and enemy reposne | C30: 4 | E30: 3, 4 | F30: this week | Z30: =($F30) -> this week | AA30: =($F30) -> this week | AB30: =($F30) -> this week | AC30: =($F30) -> this week
A31: 7 | B31: Pick up weapon | C31: 5 | E31: 4 | F31: planned | Z31: =($F31) -> planned | AA31: =($F31) -> planned | AB31: =($F31) -> planned | AC31: =($F31) -> planned | AD31: =($F31) -> planned
A32: 8 | B32: Activates special power | C32: 6 | E32: 5 | F32: planned | AE32: =($F32) -> planned | AF32: =($F32) -> planned | AG32: =($F32) -> planned | AH32: =($F32) -> planned | AI32: =($F32) -> planned | AJ32: =($F32) -> planned
A33: 9 | B33: Testing and debugging | C33: 5 | E33: 8 | F33: planned | AK33: =($F33) -> planned | AL33: =($F33) -> planned | AM33: =($F33) -> planned | AN33: =($F33) -> planned | AO33: =($F33) -> planned | AP33: =($F33) -> planned
A34: 10 | B34: Documentation | C34: 2 | E34: 9 | F34: planned | AQ34: =($F34) -> planned | AR34: =($F34) -> planned
A35: 11 | B35: Integrate With Other Components | C35: 4 | E35: 8 | F35: planned | AS35: =($F35) -> planned | AT35: =($F35) -> planned | AU35: =($F35) -> planned | AV35: =($F35) -> planned
B36: totals | C36: =SUM(C25:C35) -> 51 | D36: =SUM(D25:D35) -> 18
B37: Syed
A38: 1 | B38: Enemy Placement | C38: 2 | D38: 3 | F38: complete | G38: =($F38) -> complete | H38: =($F38) -> complete
A39: 2 | B39: Enemy Movement | C39: 2 | D39: 3 | F39: complete
A40: 3 | B40: Enemy Attack Pattern | C40: 4 | F40: this week
...

Sheet Team Mate Delverables
B2: TL 1 Deliverables | E2: TL 2 Deliverables | H2: TL 3 Deliverables | K2: TL 4 Deliverables | N2: TL 5 Deliverables | Q2: TL 6 Deliverables
B3: Date Due: 09/30 | E3: Date Due: 10/09 | H3: Date Due: 10/14 | K3: Date Due: 10/28 & 10/30 | N3: Date Due: 11/06 | Q3: Date Due: 11/13
B4: By Monday : Initial Readme File in GIT | K4: By Monday 10/27:
K5: 1. Fully update your sections of the Gantt chart | N5: 1: Update the gantt for what you have worked on.
N6: 2: Send me an update on what you have been working on this week.
K7: By Wednesday 10/29:
K8: 1. Look over the coding standards in the GIT
K9: 2. Try to update your code to comply with the coding standards (to the best of your ability, BC is not expecting it to be perfect). Message me when you're done and I'll check you off.
B15: Get deliverables to TL by 6pm on Date Due
B18: Deliverable Tracker
C20: Aiden | D20: Ro | E20: Jaskaran | F20: Safal | G20: Syed | H20: Gurneet
B21: TL 1
B22: TL 2 | D22: ü
B23: TL 3
B24: TL 4 | F24: ü
B25: TL 5
B26: TL 6

Sheet Meetings
B1: Date | C1: Aug. 30 | D1: Sept. 1 | E1: Sept. 13 | F1: Sept. 15 | G1: Sept. 21 | H1: Sept. 22 | I1: Sept. 23 | J1: Sept. 29 | K1: Oct. 4 | L1: Oct. 20
B2: Purpose | C2: First Meeting | D2: Ananlysis Planning | E2: Ananlysis Integration | F2: Ananlysis presentation practice | G2: Initial Set-up | H2: Initial Set-up | I2: Initial Set-up | J2: Initial Release | K2: Team Lead 2 demo practice | L2: Test Code Integrateion
B3: Hours | C3: 1 | D3: 4 | E3: 2 | F3: 2 | G3: 2 | H3: 2 | I3: 2 | J3: 6 | K3: 1 | L3: 8
A4: Aiden | B4: =SUMIF(C4:L4,A$12,C$3:Z$3) -> 21 | C4: ü | D4: ü | E4: ü | F4: ü | G4: ü | H4: ü | I4: ü | J4: ü
A5: Ro | B5: =SUMIF(C5:L5,A$12,C$3:Z$3) -> 9 | C5: ü | D5: ü | F5: ü | G5: ü
A6: Jaskaran | B6: =SUMIF(C6:L6,A$12,C$3:Z$3) -> 11 | C6: ü | D6: ü | E6: ü | F6: ü | H6: ü
A7: Safal | B7: =SUMIF(C7:L7,A$12,C$3:Z$3) -> 15 | C7: ü | D7: ü | E7: ü | F7: ü | G7: ü | H7: ü | I7: ü
A8: Syed | B8: =SUMIF(C8:L8,A$12,C$3:Z$3) -> 9 | C8: ü | D8: ü | E8: ü | F8: ü
A9: Gurneet | B9: =SUMIF(C9:L9,A$12,C$3:Z$3) -> 9 | C9: ü | D9: ü | E9: ü | F9: ü
A10: Total | B10: =SUM(B4:B9) -> 74 | C10: =COUNTIF(C4:C9,"*ü*") * C3 -> 6 | D10: =COUNTIF(D4:D9,"*ü*") * D3 -> 24 | E10: =COUNTIF(E4:E9,"*ü*") * E3 -> 10 | F10: =COUNTIF(F4:F9,"*ü*") * F3 -> 12 | G10: =COUNTIF(G4:G9,"*ü*") * G3 -> 6 | H10: =COUNTIF(H4:H9,"*ü*") * H3 -> 6 | I10: =COUNTIF(I4:I9,"*ü*") * I3 -> 4 | J10: =COUNTIF(J4:J9,"*ü*") * J3 -> 6 | ... L10: =COUNTIF(L4:L9,"*ü*") * L3 -> 0
A12: ü

Sheet SA
B1: Task | C1: Predicted(hrs) | D1: spent(hrs) | E1: 1 | F1: 2 | G1: 3 | H1: 4 | I1: 5 | J1: 6 | K1: 7 | L1: 8 | M1: 9 | N1: 10 | O1: 11 | P1: 12 | Q1: 13 | R1: 14 | S1: 15
A2: Anne | B2: Individual schedule | C2: 2 | D2: 2
B3: Champion | C3: 5 | D3: 6
B4: Chapter 1 and 2, glossary Terms | C4: 4 | D4: 5
B5: Subtotal | C5: =SUM(C2:C4) -> 11 | D5: =SUM(D2:D4) -> 13
A6: Bill | B6: Individual schedule | C6: 2 | D6: 3
B7: Champion | C7: 5 | D7: 2
B8: Chapter 3 and 4, glossary Terms | C8: 4 | D8: 5
B9: Subtotal | C9: =SUM(C6:C8) -> 11 | D9: =SUM(D6:D8) -> 10
A10: Chris | B10: Individual schedule | C10: 1 | D10: 1
B11: Champion | C11: 5 | D11: 8
B12: Merge schedules on google docs | C12: 2 | D12: 2 | K12: A
B13: Standardize formating | C13: 1 | D13: 1 | M13: B
B14: Assemble SA Powerpoint | C14: 2 | D14: 3 | N14: C
B15: Subtotal | C15: =SUM(C10:C14) -> 11 | D15: =SUM(D10:D14) -> 15
A16: Dan | B16: Individual schedule | C16: 2 | D16: 2
B17: Champion | C17: 5 | D17: 4
B18: Chapter 5 and 6, glossary Terms | C18: 4 | D18: 5
B19: Subtotal | C19: =SUM(C16:C18) -> 11 | D19: =SUM(D16:D18) -> 11
A20: Eric | B20: Individual schedule | C20: 2 | D20: 2
B21: Champion | C21: 5 | D21: 4
B22: Edit Chatpers 1-3 | C22: 4 | D22: 3
B23: Subtotal | C23: =SUM(C20:C22) -> 11 | D23: =SUM(D20:D22) -> 9
A24: Fran | B24: Individual schedule | C24: 2 | D24: 2
B25: Champion | C25: 5 | D25: 4
B26: Edit Chatpers 4-6 | C26: 4 | D26: 7
B27: Subtotal | C27: =SUM(C24:C26) -> 11 | D27: =SUM(D24:D26) -> 13
B28: Total | C28: =SUM(C5,C9,C15,C27) -> 44 | D28: =SUM(D5,D9,D15,D27) -> 51
B29: red is dependent on others

Sheet Overhead
B1: Anne | C1: Bill | D1: Chris | E1: Dan | F1: Eric | G1: Fran
A2: Training | B2: 10 | C2: 6 | D2: 27 | E2: 9 | F2: 9 | G2: 9
A3: SA Preesentation Prep | B3: 2 | C3: 3 | D3: 1 | E3: 6 | F3: 6 | G3: 6
A4: Software Specialist Presnetaion Prep | B4: 1 | C4: 2 | D4: 2 | E4: 1 | F4: 1 | G4: 1
A5: Team Lead Presentation Prep | B5: 4 | C5: 6 | D5: 3 | E5: 7 | F5: 7 | G5: 7
A6: Oral Exam Prep | B6: 8 | C6: 3 | D6: 9 | E6: 11 | F6: 11 | G6: 11
A7: Post Mortum Presentation Prep | B7: 1 | C7: 1 | D7: 1 | E7: 1 | F7: 1 | G7: 1
A9: Total | B9: =SUM(B2:B8) -> 26 | C9: =SUM(C2:C8) -> 21 | D9: =SUM(D2:D8) -> 43 | E9: =SUM(E2:E8) -> 35 | F9: =SUM(F2:F8) -> 35 | G9: =SUM(G2:G8) -> 35
